Workbook

Sheet Day-by-Day Plan
A1: Spring Boot + Microservices: 28-Day Plan (Mini Order System)
A2: Start date (edit): | C2: 46318 | D2: Assumption: start date is an example; change C2 and all dates update. Hours are suggested: 2 on weekdays, 3 on review days.
A4: Day | B4: Week | C4: Date | D4: Topic | E4: What to do | F4: Resources | G4: Deliverable (proof of work) | H4: Hours | I4: Status | J4: Notes
A5: 1 | B5: 1 | C5: =$C$2+A5-1 -> 46318 | D5: Setup + Hello World | E5: Install JDK 17/21, IntelliJ (or Eclipse), Maven, Git, Postman, MySQL. Generate a project at start.spring.io (Web, JPA, MySQL, H2, Lombok, Validation, Actuator). Run it and hit a /hello endpoint. | F5: spring.io guide: Building a RESTful Web Service; course intro sections | G5: Hello-world app running + pushed to GitHub | H5: 2 | I5: Done
A6: 2 | B6: 1 | C6: =$C$2+A6-1 -> 46319 | D6: Java refresher | E6: Revise lambdas, streams, Optional, records, collections (HashMap/List), exceptions. Solve 5 small stream problems. | F6: Java Brains / Telusko Java 8 playlists; Baeldung Java 8 articles | G6: 5 stream exercises in a practice repo | H6: 2 | I6: Not started
A7: 3 | B7: 1 | C7: =$C$2+A7-1 -> 46320 | D7: Spring core: IoC and DI | E7: Understand IoC container, beans, @Component/@Service/@Repository, constructor vs field injection, @Configuration/@Bean. | F7: Course: Spring Core section; Baeldung 'Spring DI' | G7: Small demo: 3 beans wired via constructor injection | H7: 2 | I7: Not started
A8: 4 | B8: 1 | C8: =$C$2+A8-1 -> 46321 | D8: REST controllers | E8: @RestController, @GetMapping/@PostMapping, @PathVariable, @RequestParam, @RequestBody, ResponseEntity, JSON mapping. | F8: Course: REST section; spring.io REST guide | G8: Product endpoints returning dummy JSON | H8: 2 | I8: Not started
A9: 5 | B9: 1 | C9: =$C$2+A9-1 -> 46322 | D9: Inventory Service v1 (in-memory) | E9: Build Product model + CRUD using an in-memory list. Layer it: Controller -> Service. Test every endpoint in Postman. | F9: Your own code + Postman | G9: Working CRUD API (no DB yet) | H9: 2 | I9: Not started
A10: 6 | B10: 1 | C10: =$C$2+A10-1 -> 46323 | D10: Config, profiles, logging, Actuator | E10: application.yml, @Value, profiles (dev/prod), SLF4J logging, Actuator /health and /info. | F10: Course: Boot config section; Baeldung Spring Profiles | G10: Dev and prod profiles, health endpoint working | H10: 2 | I10: Not started
A11: 7 | B11: 1 | C11: =$C$2+A11-1 -> 46324 | D11: Week 1 review and catch-up | E11: Revisit weak topics. Write README for Inventory Service. Push code. Quiz yourself: what is DI? what does @SpringBootApplication do? | F11: GitHub; notes | G11: Week 1 code on GitHub with README | H11: 3 | I11: Not started
A12: 8 | B12: 2 | C12: =$C$2+A12-1 -> 46325 | D12: JPA basics with H2 | E12: Entities, @Id, @GeneratedValue, JpaRepository, derived query methods. Replace the in-memory list with H2. | F12: Course: Spring Data JPA section; Baeldung JPA intro | G12: Inventory CRUD backed by H2 | H12: 2 | I12: Not started
A13: 9 | B13: 2 | C13: =$C$2+A13-1 -> 46326 | D13: Move to MySQL | E13: Create schema in MySQL, configure datasource, ddl-auto, check tables via SQL Developer/Workbench. Add custom query using @Query. | F13: MySQL docs; course JPA section | G13: Inventory service on MySQL | H13: 2 | I13: Not started
A14: 10 | B14: 2 | C14: =$C$2+A14-1 -> 46327 | D14: DTOs and layered architecture | E14: Separate Entity and DTO, add mapper (manual or MapStruct), keep controller thin, service holds logic. | F14: Baeldung 'Entity to DTO'; course | G14: DTO layer implemented | H14: 2 | I14: Not started
A15: 11 | B15: 2 | C15: =$C$2+A15-1 -> 46328 | D15: Validation | E15: @Valid, @NotNull, @Min, @NotBlank, custom validation message, validation on request DTOs. | F15: Baeldung Spring Validation | G15: Invalid requests return clear 400 errors | H15: 2 | I15: Not started
A16: 12 | B16: 2 | C16: =$C$2+A16-1 -> 46329 | D16: Global exception handling | E16: @ControllerAdvice, @ExceptionHandler, custom ResourceNotFoundException, standard error JSON, correct HTTP codes. | F16: Baeldung Error Handling for REST | G16: Consistent error responses | H16: 2 | I16: Not started
... A32: 28 | B32: 4 | C32: =$C$2+A32-1 -> 46345 | D32: Polish, resume and interview prep | E32: Clean README, architecture diagram, screenshots. Add project and skills to resume and LinkedIn. Practise a 2-minute project explanation and the Interview Topics sheet. | F32: GitHub; this workbook | G32: Public repo + updated resume | H32: 3 | I32: Not started

Sheet Requirements
A1: Project Requirements: Mini Order Management System
A2: Goal: two Spring Boot microservices (Inventory + Order) behind an API Gateway, each with its own database. Priority: Must = needed for a working demo, Should = adds interview value, Could = stretch.
A4: Total requirements | B4: =COUNTA(A9:A41) -> 33
A5: Done | B5: =COUNTIF(G9:G41,"Done") -> 0
A6: Must-haves done | B6: =COUNTIFS(E9:E41,"Must",G9:G41,"Done")&" of "&COUNTIF(E9:E41,"Must") -> 0 of 19
A8: ID | B8: Type | C8: Requirement | D8: Service | E8: Priority | F8: Build on Day | G8: Status
A9: FR-01 | B9: Functional | C9: Add a product (SKU, name, price, quantity) with a unique SKU | D9: Inventory | E9: Must | F9: 5 | G9: Not started
A10: FR-02 | B10: Functional | C10: View a product by id and by SKU | D10: Inventory | E10: Must | F10: 5 | G10: Not started
A11: FR-03 | B11: Functional | C11: List all products with pagination (page, size) and optional category filter | D11: Inventory | E11: Should | F11: 10 | G11: Not started
A12: FR-04 | B12: Functional | C12: Update product details and stock quantity | D12: Inventory | E12: Must | F12: 5 | G12: Not started
A13: FR-05 | B13: Functional | C13: Delete a product (prefer soft delete using an 'active' flag) | D13: Inventory | E13: Should | F13: 9 | G13: Not started
A14: FR-06 | B14: Functional | C14: Check availability: given SKU and quantity, return whether enough stock exists | D14: Inventory | E14: Must | F14: 18 | G14: Not started
A15: FR-07 | B15: Functional | C15: Reserve/deduct stock for an order; reject if stock is insufficient (no negative stock) | D15: Inventory | E15: Must | F15: 19 | G15: Not started
A16: FR-08 | B16: Functional | C16: Release/restore stock when an order is cancelled or fails | D16: Inventory | E16: Must | F16: 19 | G16: Not started
A17: FR-09 | B17: Functional | C17: Create an order with customer details, shipping address and one or more order lines | D17: Order | E17: Must | F17: 17 | G17: Not started
A18: FR-10 | B18: Functional | C18: Validate order input: customer name/email, at least one line, quantity > 0 | D18: Order | E18: Must | F18: 17 | G18: Not started
A19: FR-11 | B19: Functional | C19: Before confirming, call Inventory Service to check and reserve stock for every line | D19: Order | E19: Must | F19: 18 | G19: Not started
A20: FR-12 | B20: Functional | C20: Maintain order status: CREATED, CONFIRMED, FAILED, CANCELLED (like an OMS order lifecycle) | D20: Order | E20: Must | F20: 17 | G20: Not started
... A41: NFR-14 | B41: Non-functional | C41: Idempotent order creation (same request key does not create duplicate orders) | D41: Order | E41: Could | F41: 21 | G41: Not started

Sheet Data Model
A1: Data Model: Fields per Table
A2: Each service owns its own database (inventory_db, order_db). Order lines store a copy of SKU, name and price at order time (snapshot), because services do not join across databases.
A4: Service | B4: Table | C4: Field | D4: Java type | E4: Constraints | F4: Description
A5: Inventory | B5: product | C5: id | D5: Long | E5: PK, auto-generated | F5: Internal identifier
A6: Inventory | B6: product | C6: sku | D6: String(50) | E6: Unique, not null | F6: Stock keeping unit, e.g. SKU-1001
A7: Inventory | B7: product | C7: name | D7: String(150) | E7: Not null | F7: Product name
A8: Inventory | B8: product | C8: description | D8: String(500) | E8: Optional | F8: Short description
A9: Inventory | B9: product | C9: category | D9: String(80) | E9: Optional, indexed | F9: For filtering, e.g. Electronics
A10: Inventory | B10: product | C10: price | D10: BigDecimal(10,2) | E10: Not null, > 0 | F10: Unit price (never use double for money)
A11: Inventory | B11: product | C11: available_quantity | D11: Integer | E11: Not null, >= 0 | F11: Stock available to sell
A12: Inventory | B12: product | C12: reserved_quantity | D12: Integer | E12: Not null, >= 0, default 0 | F12: Stock held for confirmed orders
A13: Inventory | B13: product | C13: active | D13: Boolean | E13: Default true | F13: False = soft deleted
A14: Inventory | B14: product | C14: created_at | D14: LocalDateTime | E14: Auto-set | F14: Audit field
A15: Inventory | B15: product | C15: updated_at | D15: LocalDateTime | E15: Auto-set | F15: Audit field
... A46: Notification (optional) | B46: notification_log | C46: sent_at | D46: LocalDateTime | E46: Auto-set | F46: When processed

Sheet API Endpoints
A1: REST API Design (use for Postman and Swagger)
A2: Through the gateway, prefix with /inventory or /orders. Service ports: Inventory 8081, Order 8082, Gateway 8080, Eureka 8761.
A4: Service | B4: Method | C4: Endpoint | D4: Purpose | E4: Request body | F4: Success response | G4: Error responses
A5: Inventory | B5: POST | C5: /api/products | D5: Create product | E5: { sku, name, description, category, price, availableQuantity } | F5: 201 + product | G5: 400 invalid, 409 duplicate SKU
A6: Inventory | B6: GET | C6: /api/products/{id} | D6: Get product by id | E6: - | F6: 200 + product | G6: 404 not found
A7: Inventory | B7: GET | C7: /api/products/sku/{sku} | D7: Get product by SKU | E7: - | F7: 200 + product | G7: 404 not found
A8: Inventory | B8: GET | C8: /api/products?page=0&size=10&category= | D8: List products (paged) | E8: - | F8: 200 + page of products | G8: -
A9: Inventory | B9: PUT | C9: /api/products/{id} | D9: Update product | E9: { name, description, category, price, availableQuantity } | F9: 200 + product | G9: 400, 404
A10: Inventory | B10: DELETE | C10: /api/products/{id} | D10: Soft delete product | E10: - | F10: 204 | G10: 404
A11: Inventory | B11: GET | C11: /api/inventory/{sku}/availability?qty=5 | D11: Check stock for a SKU | E11: - | F11: 200 { sku, available, availableQuantity } | G11: 404 unknown SKU
A12: Inventory | B12: POST | C12: /api/inventory/reserve | D12: Reserve stock for an order | E12: { orderNumber, items: [ { sku, quantity } ] } | F12: 200 { reserved: true } | G12: 409 insufficient stock, 404
A13: Inventory | B13: POST | C13: /api/inventory/release | D13: Release stock (cancel/failure) | E13: { orderNumber } | F13: 200 | G13: 404 no reservation
A14: Order | B14: POST | C14: /api/orders | D14: Create and confirm an order | E14: { customerName, customerEmail, shippingAddress{...}, items: [ { sku, quantity } ] } | F14: 201 + order (status CONFIRMED) | G14: 400 invalid, 409 out of stock, 503 inventory down (fallback)
A15: Order | B15: GET | C15: /api/orders/{id} | D15: Get order by id | E15: - | F15: 200 + order with lines | G15: 404
... A19: Gateway | B19: POST | C19: /auth/login (optional) | D19: Get JWT token | E19: { username, password } | F19: 200 { token } | G19: 401 bad credentials
A21: Sample order request (copy into Postman):
A22: {"customerName":"Ravi Kumar","customerEmail":"ravi@example.com","shippingAddress":{"line":"12 MG Road","city":"Mysore","state":"Karnataka","pincode":"570001"},"items":[{"sku":"SKU-1001","quantity":2},{"sku":"SKU-1002","quantity":1}]}
A23: Note: names, email and address in the sample are made-up test data.

Sheet Tech Stack
A1: Tech Stack and Setup
A3: Area | B3: Choice | C3: Note
A4: Language | B4: Java 17 or 21 | C4: Use an LTS version
A5: Framework | B5: Spring Boot (latest stable 3.x or 4.x) | C5: Pick the version your main course uses
A6: Build tool | B6: Maven | C6: You can use Gradle if your course does
A7: Database | B7: MySQL 8 (H2 for early testing) | C7: One database per service: inventory_db, order_db
A8: Persistence | B8: Spring Data JPA / Hibernate | C8: Entities + JpaRepository
A9: Boilerplate | B9: Lombok | C9: Optional; reduces getters/setters
A10: Validation | B10: spring-boot-starter-validation | C10: @Valid, @NotNull etc.
A11: API docs | B11: springdoc-openapi | C11: Swagger UI
A12: Inter-service calls | B12: OpenFeign or RestClient | C12: Pick one and stay consistent
A13: Resilience | B13: Resilience4j | C13: Retry, timeout, circuit breaker
A14: Gateway / discovery | B14: Spring Cloud Gateway + Eureka | C14: Week 4
... A19: Source control | B19: Git + GitHub | C19: Commit daily
A21: Component | B21: Port
A22: Gateway | B22: 8080
A23: Inventory Service | B23: 8081
A24: Order Service | B24: 8082
A25: Notification Service (optional) | B25: 8083
A26: Eureka Server | B26: 8761
A27: MySQL | B27: 3306

Sheet Progress
A1: Progress Summary
A3: Week | B3: Focus | C3: Days | D3: Days done | E3: % complete | F3: Planned hours | G3: Hours completed
A4: 1 | B4: Spring Boot fundamentals | C4: =COUNTIF('Day-by-Day Plan'!$B$5:$B$32,A4) -> 7 | D4: =COUNTIFS('Day-by-Day Plan'!$B$5:$B$32,A4,'Day-by-Day Plan'!$I$5:$I$32,"Done") -> 1 | E4: =IF(C4=0,0,D4/C4) -> 0.14285714 | F4: =SUMIF('Day-by-Day Plan'!$B$5:$B$32,A4,'Day-by-Day Plan'!$H$5:$H$32) -> 15 | G4: =SUMIFS('Day-by-Day Plan'!$H$5:$H$32,'Day-by-Day Plan'!$B$5:$B$32,A4,'Day-by-Day Plan'!$I$5:$I$32,"Done") -> 2
A5: 2 | B5: Data, validation, testing | C5: =COUNTIF('Day-by-Day Plan'!$B$5:$B$32,A5) -> 7 | D5: =COUNTIFS('Day-by-Day Plan'!$B$5:$B$32,A5,'Day-by-Day Plan'!$I$5:$I$32,"Done") -> 0 | E5: =IF(C5=0,0,D5/C5) -> 0 | F5: =SUMIF('Day-by-Day Plan'!$B$5:$B$32,A5,'Day-by-Day Plan'!$H$5:$H$32) -> 15 | G5: =SUMIFS('Day-by-Day Plan'!$H$5:$H$32,'Day-by-Day Plan'!$B$5:$B$32,A5,'Day-by-Day Plan'!$I$5:$I$32,"Done") -> 0
A6: 3 | B6: Microservices + Order Service | C6: =COUNTIF('Day-by-Day Plan'!$B$5:$B$32,A6) -> 7 | D6: =COUNTIFS('Day-by-Day Plan'!$B$5:$B$32,A6,'Day-by-Day Plan'!$I$5:$I$32,"Done") -> 0 | E6: =IF(C6=0,0,D6/C6) -> 0 | F6: =SUMIF('Day-by-Day Plan'!$B$5:$B$32,A6,'Day-by-Day Plan'!$H$5:$H$32) -> 15 | G6: =SUMIFS('Day-by-Day Plan'!$H$5:$H$32,'Day-by-Day Plan'!$B$5:$B$32,A6,'Day-by-Day Plan'!$I$5:$I$32,"Done") -> 0
A7: 4 | B7: Gateway, security, Docker, polish | C7: =COUNTIF('Day-by-Day Plan'!$B$5:$B$32,A7) -> 7 | D7: =COUNTIFS('Day-by-Day Plan'!$B$5:$B$32,A7,'Day-by-Day Plan'!$I$5:$I$32,"Done") -> 0 | E7: =IF(C7=0,0,D7/C7) -> 0 | F7: =SUMIF('Day-by-Day Plan'!$B$5:$B$32,A7,'Day-by-Day Plan'!$H$5:$H$32) -> 16 | G7: =SUMIFS('Day-by-Day Plan'!$H$5:$H$32,'Day-by-Day Plan'!$B$5:$B$32,A7,'Day-by-Day Plan'!$I$5:$I$32,"Done") -> 0
A8: Total | C8: =SUM(C4:C7) -> 28 | D8: =SUM(D4:D7) -> 1 | E8: =IF(C8=0,0,D8/C8) -> 0.035714286 | F8: =SUM(F4:F7) -> 61 | G8: =SUM(G4:G7) -> 2
A10: How to use: change the Status column on the Day-by-Day Plan sheet to 'Done' and this table updates automatically.

Sheet Courses
A1: Recommended Courses and Resources
A2: Prices and course versions change often. Check the listing is current (Spring Boot 3 or 4, Java 17+) before buying; Udemy runs frequent sales.
A4: Type | B4: Course / Resource | C4: Platform | D4: Use it for | E4: Use in weeks | F4: Cost
A5: Pick ONE main course | B5: Spring Boot 4, Spring 7 & Hibernate for Beginners (Chad Darby) | C5: Udemy | D5: Complete Spring Boot foundation: DI, REST, JPA | E5: 1-2 | F5: Paid
A6: Pick ONE main course | B6: Learn Spring Boot 3 in 100 Steps (in28Minutes) | C6: Udemy | D6: Faster, hands-on alternative if you already know Java well (Purchased. 208 lectures, about 18 hrs; see the Course Mapping sheet.) | E6: 1-2 | F6: Paid
A7: Microservices (main) | B7: Master Microservices with Spring Boot and Spring Cloud (in28Minutes) | C7: Udemy | D7: Gateway, Eureka, Resilience4j, Docker, inter-service calls (Purchased. 286 lectures, about 22.5 hrs; see the Course Mapping sheet.) | E7: 3-4 | F7: Paid
A8: Microservices (alt) | B8: Master Microservices with Spring Boot, Docker, Kubernetes | C8: Udemy | D8: Same topics plus Docker and Kubernetes depth | E8: 3-4 | F8: Paid
A9: Microservices (alt) | B9: Building Scalable Java Microservices with Spring Boot and Spring Cloud | C9: Coursera (Google Cloud) | D9: Structured course; can audit/free trial depending on current offer | E9: 3-4 | F9: Free audit or paid
A10: Free / official | B10: Spring Academy (spring.academy) | C10: Spring (VMware/Broadcom) | D10: Official free courses on Spring Boot, REST and testing | E10: 1-2 | F10: Free
A11: Free / official | B11: Guides at spring.io/guides | C11: spring.io | D11: Short step-by-step guides: REST, JPA, Gateway, Security | E11: All | F11: Free
A12: Free / reference | B12: Baeldung Spring tutorials | C12: baeldung.com | D12: Quick articles for validation, error handling, Feign, JWT | E12: All | F12: Free (some paid)
A13: Free / reference | B13: Microservices.io patterns (Chris Richardson) | C13: microservices.io | D13: API gateway, saga, circuit breaker concepts | E13: 3 | F13: Free
A14: Free / video | B14: Amigoscode, Java Brains, Telusko Spring Boot playlists | C14: YouTube | D14: Free video alternative to Udemy for basics | E14: 1-3 | F14: Free
A15: Tools | B15: Postman, Docker Desktop, IntelliJ Community, MySQL | C15: Local | D15: Everything you need to run the project | E15: All | F15: Free
A17: Suggested path: ONE main Spring Boot course (weeks 1-2) + ONE microservices course (weeks 3-4). Do not buy many courses; build the project instead.

Sheet Course Mapping
A1: Course Mapping: both courses to the 28-Day Plan
A2: C1 = Learn Spring Boot 3 in 100 Steps (208 lectures, ~18 hrs). C2 = Master Microservices with Spring Boot and Spring Cloud (286 lectures, ~22.5 hrs). Lecture numbers are the numbers shown on Udemy. Watching only the lectures listed in Part 1 is roughly 15 hours across both courses. Play at 1.25-1.5x, then code your own service.
A4: Plan rows done: | B4: =COUNTIF(G8:G35,"Done")&" of "&COUNTA(A8:A35) -> 1 of 28
A6: Part 1: What to watch on each plan day
A7: Plan day(s) | B7: Plan topic | C7: Primary lectures (watch these) | D7: Optional / alternate | E7: Video time | F7: What to do alongside | G7: Watch status
A8: Day 1 | B8: Setup + Hello World | C8: C1 Sec 1-2: lectures 1-12 (intro, Initializr, Hello World API) | E8: ~35 min | F8: Create your own project, run it, push to GitHub | G8: Done
A9: Day 1 (remaining) | B9: Finish Spring Boot intro | C9: C1 Sec 2: lectures 13-26 (starters, auto-configuration, DevTools, Boot vs Spring vs MVC) | D9: Lectures 19, 25, 26 are non-technical | E9: ~1 hr | F9: Be able to explain @SpringBootApplication and a starter | G9: Not started
A10: Day 2 | B10: Java refresher | C10: C1 Sec 13: lectures 199-207 (lambdas, filter, map, streams, Optional) | D10: C1 194-197 Java new features. C2 Sec 16 (271-279) is the same content | E10: ~50 min | F10: Do the exercise list: streams, Optional, records, collections | G10: Not started
A11: Day 3 | B11: Spring core: IoC and DI | C11: C1 Sec 9: 158-164, 166-167, 171-172 (tight vs loose coupling, DI types, modules) | D11: C2 Sec 10 (206-221) is the same content | E11: ~1 hr | F11: Write 3 beans wired by constructor injection | G11: Not started
A12: Day 4 | B12: REST controllers | C12: C2 Sec 3: 14, 16, 17, 19, 20, 22 (Hello World REST, bean, auto-config, path variable) | D12: C2 21 (Boot 4 update). C1 122-131 as an alternative | E12: ~40 min | F12: Build Product GET endpoints returning JSON | G12: Not started
A13: Day 5 | B13: Inventory Service v1 | C13: C2 Sec 3: 23, 24, 26, 27, 28, 33 (API design, DAO service, GET, POST, status code + Location, DELETE) and C1 139 (PUT) | D13: C1 132-138 (best practices, status codes) | E13: ~50 min | F13: Build your own Product CRUD; do not copy the Social Media code | G13: Not started
A14: Day 6 | B14: Config, profiles, logging, Actuator | C14: C1 Sec 2: 18, 20, 21, 22 (profiles, ConfigurationProperties, embedded servers, Actuator). C1 Sec 4: 52 (logging) | D14: C2 48 (Actuator for REST APIs) | E14: ~50 min | F14: Add dev/prod profiles and /actuator/health | G14: Not started
A15: Day 8 | B15: JPA with H2 | C15: C2 Sec 3: 51-54 (H2 console, User entity, REST to H2 with JPA; lecture 52 is a must-read) and C1 93 (JpaRepository) | D15: C2 106-107 (Boot 4 H2 changes). C1 Sec 10 (176-189) for depth | E15: ~30 min | F15: Replace the in-memory list with a JpaRepository | G15: Not started
A16: Day 9 | B16: Move to MySQL | C16: C2 Sec 3: 59, 62, 63 (MySQL overview, connector changes, implementation) | D16: C2 60 (Docker install, optional). C1 94, 98, 99 as alternate | E16: ~20 min | F16: Use MySQL on your Mac, or Docker if you prefer | G16: Not started
A17: Day 10 | B17: DTOs and layered architecture | C17: No lecture covers DTOs. Related: C2 24 (DAO/service layer) | D17: C2 46-47 (JSON filtering, an alternative to DTOs, interview topic) | E17: - | F17: Use Baeldung: Entity to DTO conversion | G17: Not started
A18: Day 11 | B18: Validation | C18: C2 Sec 3: 34 (validations for REST API) | D18: C1 69-70 (web form version) | E18: ~12 min | F18: Apply @Valid to your request DTOs | G18: Not started
A19: Day 12 | B19: Global exception handling | C19: C2 Sec 3: 30, 32 (404 not found, generic exception handling for all resources) | D19: - | E19: ~20 min | F19: Add @ControllerAdvice with a consistent error JSON | G19: Not started
A20: Day 13 | B20: Testing | C20: C1 Sec 5: 101-105 (JUnit). C1 Sec 6: 107-112 (Mockito). C1 Sec 8: 150, 152, 153 (MockMvc tests) | D20: C1 144-148 integration tests (do on Day 14 if time allows) | E20: ~1 hr 45 min | F20: Write 6+ tests for your service layer and controller | G20: Not started
... A35: Day 28 | B35: Polish, resume and interview prep | C35: No lectures | D35: Interview Topics sheet | E35: - | F35: README, architecture diagram, resume update | G35: Not started
A38: Part 2: Course 1 (Learn Spring Boot 3 in 100 Steps): all 13 sections
A39: Section | B39: Name | C39: Lectures | D39: Duration | E39: Use for project | F39: Notes | G39: Watch status
A40: C1 Sec 1 | B40: Introduction | C40: 1-6 | D40: 9 min | E40: Done | F40: Already completed | G40: Done
A41: C1 Sec 2 | B41: Introduction to Spring Boot in 10 Steps - V2 | C41: 7-26 | D41: 1 hr 23 min | E41: Watch | F41: Core. Done up to lecture 12; 13-26 left | G41: In progress
A42: C1 Sec 3 | B42: Introduction to Maven | C42: 27-38 | D42: 1 hr | E42: Skim | F42: Only if Maven is unclear. Same as C2 Sec 4 | G42: Not started
A43: C1 Sec 4 | B43: Web Application with Spring Boot - V2 | C43: 39-100 | D43: 5 hr 57 min | E43: Selective | F43: JSP Todo app, mostly not needed. Take 52 (logging); 78-82 optional (security) | G43: Not started
A44: C1 Sec 5 | B44: Introduction to JUnit in 5 Steps - V2 | C44: 101-106 | D44: 39 min | E44: Watch | F44: Day 13 | G44: Not started
A45: C1 Sec 6 | B45: Introduction to Mockito in 5 Steps - V2 | C45: 107-113 | D45: 38 min | E45: Watch | F45: Day 13 | G45: Not started
A46: C1 Sec 7 | B46: Introduction to Gradle | C46: 114-121 | D46: 26 min | E46: Skip | F46: Your project uses Maven | G46: Not started
A47: C1 Sec 8 | B47: Spring Boot Deep Dive with a REST API - V2 | C47: 122-157 | D47: 3 hr 50 min | E47: Selective | F47: Now used for testing (150, 152, 153; optional 144-148), PUT (139) and REST security (154-156). REST CRUD basics come from C2 Sec 3 | G47: Not started
A48: C1 Sec 9 | B48: Appendix - Introduction to Spring Framework | C48: 158-175 | D48: 1 hr 26 min | E48: Watch | F48: DI and loose coupling (Day 3) | G48: Not started
A49: C1 Sec 10 | B49: Appendix - Introduction to JPA With Spring Boot in 10 Steps | C49: 176-189 | D49: 1 hr 16 min | E49: Optional | F49: Deeper JPA, good for interviews | G49: Not started
A50: C1 Sec 11 | B50: Congratulations | C50: 190-192 | D50: 1 min | E50: Skip | F50: Non-technical | G50: Not started
... A52: C1 Sec 13 | B52: Appendix - Functional Programming in 30 Minutes | C52: 199-208 | D52: 50 min | E52: Watch | F52: Day 2 | G52: Not started
A55: Part 3: Course 2 (Master Microservices with Spring Boot and Spring Cloud): all 17 sections
A56: Section | B56: Name | C56: Lectures | D56: Duration | E56: Use for project | F56: Notes | G56: Watch status
A57: C2 Sec 1 | B57: Getting Started | C57: 1-5 | D57: 8 min | E57: Skip | F57: Intro only | G57: Not started
A58: C2 Sec 2 | B58: Introduction To Web Services | C58: 6-10 | D58: 15 min | E58: Optional | F58: Lecture 10 (SOAP vs REST) is a common interview question | G58: Not started
A59: C2 Sec 3 | B59: Restful Web Services with Spring Boot | C59: 11-66 | D59: 5 hr 9 min | E59: Watch (selected) | F59: Take 14-28, 30, 32-34, 36-38, 51-58, 59, 62-65. Optional: 39-47 (XML, i18n, versioning, HATEOAS, filtering), 48-49 (Actuator, HAL) | G59: Not started
A60: C2 Sec 4 | B60: Introduction to Maven | C60: 67-78 | D60: 1 hr | E60: Skip | F60: Same lecture titles as C1 Sec 3 | G60: Not started
A61: C2 Sec 5 | B61: Introduction To Microservices | C61: 79-84 | D61: 20 min | E61: Watch | F61: Day 15 | G61: Not started
...

Sheet Interview Topics
A1: Interview Topics Checklist
A3: # | B3: Topic | C3: Be able to explain | D3: Ready?
A4: 1 | B4: What is Spring Boot and how does auto-configuration work? | C4: Starters, @SpringBootApplication = 3 annotations, conditional beans | D4: No
A5: 2 | B5: IoC and Dependency Injection | C5: Container, beans, constructor injection preferred over field injection | D5: No
A6: 3 | B6: Bean scopes and lifecycle | C6: singleton vs prototype, @PostConstruct, @PreDestroy | D6: No
A7: 4 | B7: @Component vs @Service vs @Repository vs @Controller | C7: Stereotypes, exception translation for @Repository | D7: No
A8: 5 | B8: REST principles and HTTP methods/status codes | C8: GET/POST/PUT/PATCH/DELETE, idempotency, 200/201/400/404/500 | D8: No
A9: 6 | B9: Spring Data JPA | C9: Entity, repository, lazy vs eager, N+1 problem, @Transactional | D9: No
A10: 7 | B10: Exception handling and validation | C10: @ControllerAdvice, @Valid, custom exceptions | D10: No
A11: 8 | B11: Profiles and externalized configuration | C11: application.yml, profiles, environment variables | D11: No
A12: 9 | B12: Monolith vs microservices | C12: Trade-offs, when NOT to use microservices | D12: No
A13: 10 | B13: Service communication | C13: REST/Feign vs messaging, sync vs async | D13: No
A14: 11 | B14: API Gateway and service discovery | C14: Why Gateway, how Eureka works, load balancing | D14: No
A15: 12 | B15: Resilience patterns | C15: Circuit breaker, retry, timeout, fallback | D15: No
... A23: 20 | B23: SQL | C23: Joins, indexes, group by, transactions | D23: No
B25: Topics ready: | C25: =COUNTIF(D4:D23,"Yes")&" of "&COUNTA(B4:B23) -> 0 of 20
